
(venv) C:\Users\Gokova\OneDrive - CELEBI HAVACILIK HOLDING A.S\Personel\Programming\Python\backend>uvicorn main:app --reload  --env-file "..\.env.local"
←[32mINFO←[0m:     Will watch for changes in these directories: ['C:\\Users\\Gokova\\OneDrive - CELEBI HAVACILIK HOLDING A.S\\Personel\\Programming\\Python\\backend']
←[32mINFO←[0m:     Loading environment from '..\.env.local'
←[32mINFO←[0m:     Uvicorn running on ←[1mhttp://127.0.0.1:8000←[0m (Press CTRL+C to quit)
←[32mINFO←[0m:     Started reloader process [←[36m←[1m15092←[0m] using ←[36m←[1mWatchFiles←[0m
C:\Users\Gokova\OneDrive - CELEBI HAVACILIK HOLDING A.S\Personel\Programming\Python\backend\venv\Lib\site-packages\pydantic\_internal\_config.py:373: UserWarning: Valid config keys have changed in V2:
* 'orm_mode' has been renamed to 'from_attributes'
  warnings.warn(message, UserWarning)
←[32mINFO←[0m:     Started server process [←[36m26232←[0m]
←[32mINFO←[0m:     Waiting for application startup.
←[32mINFO←[0m:     Application startup complete.
←[32mINFO←[0m:     127.0.0.1:53612 - "←[1mPUT /api/v1/yemek-cekiler/1 HTTP/1.1←[0m" ←[91m500 Internal Server Error←[0m
←[31mERROR←[0m:    Exception in ASGI application
Traceback (most recent call last):
  File "C:\Users\Gokova\OneDrive - CELEBI HAVACILIK HOLDING A.S\Personel\Programming\Python\backend\venv\Lib\site-packages\uvicorn\protocols\http\httptools_impl.py", line 409, in run_asgi
    result = await app(  # type: ignore[func-returns-value]
             ^^^^^^^^^^^^^^^^^^^^^^^^^^^^^^^^^^^^^^^^^^^^^^
        self.scope, self.receive, self.send
        ^^^^^^^^^^^^^^^^^^^^^^^^^^^^^^^^^^^
    )
    ^
  File "C:\Users\Gokova\OneDrive - CELEBI HAVACILIK HOLDING A.S\Personel\Programming\Python\backend\venv\Lib\site-packages\uvicorn\middleware\proxy_headers.py", line 60, in __call__
    return await self.app(scope, receive, send)
           ^^^^^^^^^^^^^^^^^^^^^^^^^^^^^^^^^^^^
  File "C:\Users\Gokova\OneDrive - CELEBI HAVACILIK HOLDING A.S\Personel\Programming\Python\backend\venv\Lib\site-packages\fastapi\applications.py", line 1054, in __call__
    await super().__call__(scope, receive, send)
  File "C:\Users\Gokova\OneDrive - CELEBI HAVACILIK HOLDING A.S\Personel\Programming\Python\backend\venv\Lib\site-packages\starlette\applications.py", line 112, in __call__
    await self.middleware_stack(scope, receive, send)
  File "C:\Users\Gokova\OneDrive - CELEBI HAVACILIK HOLDING A.S\Personel\Programming\Python\backend\venv\Lib\site-packages\starlette\middleware\errors.py", line 187, in __call__
    raise exc
  File "C:\Users\Gokova\OneDrive - CELEBI HAVACILIK HOLDING A.S\Personel\Programming\Python\backend\venv\Lib\site-packages\starlette\middleware\errors.py", line 165, in __call__
    await self.app(scope, receive, _send)
  File "C:\Users\Gokova\OneDrive - CELEBI HAVACILIK HOLDING A.S\Personel\Programming\Python\backend\venv\Lib\site-packages\starlette\middleware\cors.py", line 93, in __call__
    await self.simple_response(scope, receive, send, request_headers=headers)
  File "C:\Users\Gokova\OneDrive - CELEBI HAVACILIK HOLDING A.S\Personel\Programming\Python\backend\venv\Lib\site-packages\starlette\middleware\cors.py", line 144, in simple_response
    await self.app(scope, receive, send)
  File "C:\Users\Gokova\OneDrive - CELEBI HAVACILIK HOLDING A.S\Personel\Programming\Python\backend\venv\Lib\site-packages\starlette\middleware\exceptions.py", line 62, in __call__
    await wrap_app_handling_exceptions(self.app, conn)(scope, receive, send)
  File "C:\Users\Gokova\OneDrive - CELEBI HAVACILIK HOLDING A.S\Personel\Programming\Python\backend\venv\Lib\site-packages\starlette\_exception_handler.py", line 53, in wrapped_app
    raise exc
  File "C:\Users\Gokova\OneDrive - CELEBI HAVACILIK HOLDING A.S\Personel\Programming\Python\backend\venv\Lib\site-packages\starlette\_exception_handler.py", line 42, in wrapped_app
    await app(scope, receive, sender)
  File "C:\Users\Gokova\OneDrive - CELEBI HAVACILIK HOLDING A.S\Personel\Programming\Python\backend\venv\Lib\site-packages\starlette\routing.py", line 714, in __call__
    await self.middleware_stack(scope, receive, send)
  File "C:\Users\Gokova\OneDrive - CELEBI HAVACILIK HOLDING A.S\Personel\Programming\Python\backend\venv\Lib\site-packages\starlette\routing.py", line 734, in app
    await route.handle(scope, receive, send)
  File "C:\Users\Gokova\OneDrive - CELEBI HAVACILIK HOLDING A.S\Personel\Programming\Python\backend\venv\Lib\site-packages\starlette\routing.py", line 288, in handle
    await self.app(scope, receive, send)
  File "C:\Users\Gokova\OneDrive - CELEBI HAVACILIK HOLDING A.S\Personel\Programming\Python\backend\venv\Lib\site-packages\starlette\routing.py", line 76, in app
    await wrap_app_handling_exceptions(app, request)(scope, receive, send)
  File "C:\Users\Gokova\OneDrive - CELEBI HAVACILIK HOLDING A.S\Personel\Programming\Python\backend\venv\Lib\site-packages\starlette\_exception_handler.py", line 53, in wrapped_app
    raise exc
  File "C:\Users\Gokova\OneDrive - CELEBI HAVACILIK HOLDING A.S\Personel\Programming\Python\backend\venv\Lib\site-packages\starlette\_exception_handler.py", line 42, in wrapped_app
    await app(scope, receive, sender)
  File "C:\Users\Gokova\OneDrive - CELEBI HAVACILIK HOLDING A.S\Personel\Programming\Python\backend\venv\Lib\site-packages\starlette\routing.py", line 73, in app
    response = await f(request)
               ^^^^^^^^^^^^^^^^
  File "C:\Users\Gokova\OneDrive - CELEBI HAVACILIK HOLDING A.S\Personel\Programming\Python\backend\venv\Lib\site-packages\fastapi\routing.py", line 301, in app
    raw_response = await run_endpoint_function(
                   ^^^^^^^^^^^^^^^^^^^^^^^^^^^^
    ...<3 lines>...
    )
    ^
  File "C:\Users\Gokova\OneDrive - CELEBI HAVACILIK HOLDING A.S\Personel\Programming\Python\backend\venv\Lib\site-packages\fastapi\routing.py", line 214, in run_endpoint_function
    return await run_in_threadpool(dependant.call, **values)
           ^^^^^^^^^^^^^^^^^^^^^^^^^^^^^^^^^^^^^^^^^^^^^^^^^
  File "C:\Users\Gokova\OneDrive - CELEBI HAVACILIK HOLDING A.S\Personel\Programming\Python\backend\venv\Lib\site-packages\starlette\concurrency.py", line 37, in run_in_threadpool
    return await anyio.to_thread.run_sync(func)
           ^^^^^^^^^^^^^^^^^^^^^^^^^^^^^^^^^^^^
  File "C:\Users\Gokova\OneDrive - CELEBI HAVACILIK HOLDING A.S\Personel\Programming\Python\backend\venv\Lib\site-packages\anyio\to_thread.py", line 56, in run_sync
    return await get_async_backend().run_sync_in_worker_thread(
           ^^^^^^^^^^^^^^^^^^^^^^^^^^^^^^^^^^^^^^^^^^^^^^^^^^^^
        func, args, abandon_on_cancel=abandon_on_cancel, limiter=limiter
        ^^^^^^^^^^^^^^^^^^^^^^^^^^^^^^^^^^^^^^^^^^^^^^^^^^^^^^^^^^^^^^^^
    )
    ^
  File "C:\Users\Gokova\OneDrive - CELEBI HAVACILIK HOLDING A.S\Personel\Programming\Python\backend\venv\Lib\site-packages\anyio\_backends\_asyncio.py", line 2470, in run_sync_in_worker_thread
    return await future
           ^^^^^^^^^^^^
  File "C:\Users\Gokova\OneDrive - CELEBI HAVACILIK HOLDING A.S\Personel\Programming\Python\backend\venv\Lib\site-packages\anyio\_backends\_asyncio.py", line 967, in run
    result = context.run(func, *args)
  File "C:\Users\Gokova\OneDrive - CELEBI HAVACILIK HOLDING A.S\Personel\Programming\Python\backend\api\v1\endpoints\yemek_ceki.py", line 32, in update_yemek_ceki
    db_yemek_ceki = crud.update_yemek_ceki(db=db, yemek_ceki_id=yemek_ceki_id, yemek_ceki=yemek_ceki_data)
TypeError: update_yemek_ceki() got an unexpected keyword argument 'yemek_ceki'. Did you mean 'yemek_ceki_id'?
